Workbook

Sheet ΚΤΗΡΙΟ
A1: SRId | B1: BUILDING ID | C1: AREA TYPE | D1: ΟΡΟΦΟΙ | E1: ΟΡΟΦΟΣ ΠΕΛΑΤΗ | F1: ΟΡΟΦΟΣ BEP | G1: ΥΠΟΓΡΑΦΗ ΔΙΑΧΕΙΡΙΣΤΗ | H1: BEP ONLY | I1: BEP TEMPLATE | J1: BEP TYPE | K1: BMO TYPE | L1: ΥΠΟΔΟΜΗ ΑΠΟ ΔΕΗ-ΚΑΤΑΣΚΕΥΗ ΜΕ NANOTRONIX | M1: NANOTRONIX | N1: SMART READINESS | O1: ΣΥΣΧΕΤΙΣΜΕΝΟ BCP | P1: ΚΟΝΤΙΝΟ BCP | Q1: ΝΕΟ BCP | R1: CONDUIT | S1: ΑΠΟΣΤΑΣΗ ΑΠΟ ΚΑΜΠΙΝΑ | T1: LATITUDE | U1: LONGITUDE | V1: NOTES | W1: WARNING | X1: FAILURE
A2: 2-339414353721 | B2: 754086020 | C2: OTE | D2: 5 | E2: +03 | F2: +00 | G2: TRUE | H2: FALSE | I2: BEP 4SP 1:8(01a..09d) ΟΔ | J2: X-LARGE/48/RAYCAP | K2: LARGE/80/RAYCAP | L2: FALSE | M2: FALSE | N2: FALSE | R2: b09 | S2: 225 | T2: 37964513 | U2: 23565680

Sheet ΟΡΟΦΟΙ
A1: ΟΡΟΦΟΣ | B1: ΔΙΑΜΕΡΙΣΜΑΤΑ | C1: ΚΑΤΑΣΤΗΜΑΤΑ | D1: FB01 | E1: FB01 TYPE | F1: FB02 | G1: FB02 TYPE | H1: FB03 | I1: FB03 TYPE | J1: FB04 | K1: FB04 TYPE | L1: FB ΠΕΛΑΤΗ | M1: ΑΡΙΘΜΗΣΗ ΧΩΡΟΥ ΠΕΛΑΤΗ | N1: GIS ID
A2: -01 | B2: 0 | C2: 0
A3: +00 | B3: 0 | C3: 8 | D3: 6 | E3: FB 12 PORTS | F3: 2 | G3: FB 12 PORTS
A4: +01 | B4: 6 | C4: 0 | D4: 6 | E4: FB 12 PORTS
A5: +02 | B5: 6 | C5: 0 | D5: 6 | E5: FB 12 PORTS
A6: +03 | B6: 6 | C6: 0 | D6: 6 | E6: FB 12 PORTS | L6: FB(+03).1 | M6: Γ1

Sheet OPTICAL PATHS
A1: OPTICAL PATH TYPE | B1: OPTICAL PATH | C1: GISID
A2: CAB-BEP | B2: G489_SGA03(1:8).02_B1.9_BEP01(b09)_01a_SB01(1:8)
A3: CAB-BEP | B3: G489_SGA03(1:8).03_B1.10_BEP01(b09)_01b_SB02(1:8)
A4: CAB-BEP | B4: G489_SGA03(1:8).04_B1.11_BEP01(b09)_01c_SB03(1:8)
A5: CAB-BEP | B5: G489_SGA03(1:8).05_B1.12_BEP01(b09)_01d_SB04(1:8)
A6: BEP-BMO | B6: BEP01(b09)_SB01(1:8).01_02a_BMO01_1
A7: BEP-BMO | B7: BEP01(b09)_SB01(1:8).02_02b_BMO01_2
A8: BEP-BMO | B8: BEP01(b09)_SB01(1:8).03_02c_BMO01_3
A9: BEP-BMO | B9: BEP01(b09)_SB01(1:8).04_02d_BMO01_4
A10: BEP-BMO | B10: BEP01(b09)_SB01(1:8).05_03a_BMO01_5
A11: BEP-BMO | B11: BEP01(b09)_SB01(1:8).06_03b_BMO01_6
A12: BEP-BMO | B12: BEP01(b09)_SB01(1:8).07_03c_BMO01_13
A13: BEP-BMO | B13: BEP01(b09)_SB01(1:8).08_03d_BMO01_14
... A89: BMO-FB | B89: BMO01_9_FB(+00).1_09

Sheet ΕΡΓΑΣΙΕΣ
A1: ΤΥΠΟΣ ΕΡΓΑΣΙΑΣ | B1: ΕΡΓΑΣΙΑ | C1: ΠΟΣΟΤΗΤΑ | D1: ΟΡΟΦΟΣ

Sheet LABELS BMO
Y1: OPTICAL PATH | Z1: index for bep | AA1: =MID(Y1,12,9) -> H | AC1: =MID(Y1,29,9)
P2: ΒΜΟ XLARGE BEP with 1 splitter | X2: 1 | Z2: =MID(Y2,1,9) | AA2: =MID(Y2,11,12) | AC2: =MID(Y2,29,13) | AD2: 1 | AE2: =CONCATENATE(AA2,AB2,AC2)
A3: Medium BMO with 1 splitter | H3: ΒΜΟ LARGE BEP with 1 splitter | P3: ΘΕΣΗ | Q3: A | R3: ΘΕΣΗ | S3: B | T3: ΠΑΡΑΤΗΡΗΣΕΙΣ | X3: 2 | Z3: =MID(Y3,1,9) | AA3: =MID(Y3,11,12) | AC3: =MID(Y3,29,13) | AD3: 2 | AE3: =CONCATENATE(AA3,AB3,AC3)
A4: ΘΕΣΗ | B4: Α | C4: ΘΕΣΗ | D4: Β | E4: ΠΑΡΑΤΗΡΗΣΕΙΣ | H4: ΘΕΣΗ | I4: A | J4: B | K4: C | L4: D | M4: ΠΑΡΑΤΗΡΗΣΕΙΣ | P4: 1 | Q4: 1 | R4: 25 | S4: 2 | T4: από καμπίνα | X4: 3 | Z4: =MID(Y4,1,9) | AA4: =MID(Y4,11,12) | AC4: =MID(Y4,29,13) | AD4: 3 | AE4: =CONCATENATE(AA4,AB4,AC4)
A5: 1 | B5: =AE2 | C5: 1 | D5: =AE3 | E5: από καμπίνα | H5: 1 | M5: από καμπίνα | P5: 2 | Q5: 3 | R5: 26 | S5: 4 | X5: 4 | Z5: =MID(Y5,1,9) | AA5: =MID(Y5,11,12) | AC5: =MID(Y5,29,13) | AD5: 4 | AE5: =CONCATENATE(AA5,AB5,AC5)
A6: 2 | B6: =AE4 | C6: 2 | D6: =AE5 | H6: 2 | I6: =AE2 | J6: =AE3 | K6: =AE4 | L6: =AE5 | P6: 3 | Q6: =$AE$2 | R6: 27 | S6: =$AE$3 | X6: 5 | Z6: =MID(Y6,1,9) | AA6: =MID(Y6,11,12) | AC6: =MID(Y6,29,13) | AD6: 5 | AE6: =CONCATENATE(AA6,AB6,AC6)
A7: 3 | B7: =AE6 | C7: 3 | D7: =AE7 | H7: 3 | I7: =AE6 | J7: =AE7 | K7: =AE8 | L7: =AE9 | P7: 4 | Q7: =$AE$4 | R7: 28 | S7: =$AE$5 | X7: 6 | Z7: =MID(Y7,1,9) | AA7: =MID(Y7,11,12) | AC7: =MID(Y7,29,13) | AD7: 6 | AE7: =CONCATENATE(AA7,AB7,AC7)
A8: 4 | B8: =AE8 | C8: 4 | D8: =AE9 | H8: 4 | I8: =AE10 | J8: =AE11 | K8: =AE12 | L8: =AE13 | P8: 5 | Q8: =$AE$6 | R8: 29 | S8: =$AE$7 | X8: 7 | Z8: =MID(Y8,1,9) | AA8: =MID(Y8,11,12) | AC8: =MID(Y8,29,13) | AD8: 7 | AE8: =CONCATENATE(AA8,AB8,AC8)
A9: 5 | B9: =AE10 | C9: 5 | D9: =AE11 | H9: 5 | I9: =AE14 | J9: =AE15 | K9: =AE16 | L9: =AE17 | P9: 6 | Q9: =$AE$8 | R9: 30 | S9: =$AE$9 | X9: 8 | Z9: =MID(Y9,1,9) | AA9: =MID(Y9,11,12) | AC9: =MID(Y9,29,13) | AD9: 8 | AE9: =CONCATENATE(AA9,AB9,AC9)
A10: 6 | B10: =AE12 | C10: 6 | D10: =AE13 | H10: 6 | I10: =AE18 | J10: =AE19 | K10: =AE20 | L10: =AE21 | P10: 7 | Q10: =$AE$10 | R10: 31 | S10: =$AE$11 | X10: 9 | Z10: =MID(Y10,1,9) | AA10: =MID(Y10,11,12) | AC10: =MID(Y10,29,13) | AD10: 9 | AE10: =CONCATENATE(AA10,AB10,AC10)
A11: 7 | B11: - | C11: 7 | D11: - | E11: χωρίς ports | H11: 7 | I11: =AE22 | J11: =AE23 | K11: =AE24 | L11: =AE25 | P11: 8 | Q11: =$AE$12 | R11: 32 | S11: =$AE$13 | X11: 10 | Z11: =MID(Y11,1,9) | AA11: =MID(Y11,11,12) | AC11: =MID(Y11,29,13) | AD11: 10 | AE11: =CONCATENATE(AA11,AB11,AC11)
A12: 8 | B12: - | C12: 8 | D12: - | E12: χωρίς ports | H12: 8 | I12: =AE26 | J12: =AE27 | K12: =AE28 | L12: =AE29 | P12: 9 | Q12: =$AE$14 | R12: 33 | S12: =$AE$15 | X12: 11 | Z12: =MID(Y12,1,9) | AA12: =MID(Y12,11,12) | AC12: =MID(Y12,29,13) | AD12: 11 | AE12: =CONCATENATE(AA12,AB12,AC12)
H13: 9 | I13: =AE30 | J13: =AE31 | K13: =AE32 | L13: =AE33 | P13: 10 | Q13: =$AE$16 | R13: 34 | S13: =$AE$17 | X13: 12 | Z13: =MID(Y13,1,9) | AA13: =MID(Y13,11,12) | AC13: =MID(Y13,29,13) | AD13: 12 | AE13: =CONCATENATE(AA13,AB13,AC13)
P14: 11 | Q14: =$AE$18 | R14: 35 | S14: =$AE$19 | X14: 13 | Z14: =MID(Y14,1,9) | AA14: =MID(Y14,11,12) | AC14: =MID(Y14,29,13) | AD14: 13 | AE14: =CONCATENATE(AA14,AB14,AC14)
H15: SMALL BEP with 1 splitter | P15: 12 | Q15: =$AE$20 | R15: 36 | S15: =$AE$21 | X15: 14 | Z15: =MID(Y15,1,9) | AA15: =MID(Y15,11,12) | AC15: =MID(Y15,29,13) | AD15: 14 | AE15: =CONCATENATE(AA15,AB15,AC15)
H16: ΘΕΣΗ | I16: A | J16: B | K16: ΠΑΡΑΤΗΡΗΣΕΙΣ | P16: 13 | Q16: =$AE$22 | R16: 37 | S16: =$AE$23 | X16: 15 | Z16: =MID(Y16,1,9) | AA16: =MID(Y16,11,12) | AC16: =MID(Y16,29,13) | AD16: 15 | AE16: =CONCATENATE(AA16,AB16,AC16)
H17: 1 | P17: 14 | Q17: =$AE$24 | R17: 38 | S17: =$AE$25 | X17: 16 | Z17: =MID(Y17,1,9) | AA17: =MID(Y17,11,12) | AC17: =MID(Y17,29,13) | AD17: 16 | AE17: =CONCATENATE(AA17,AB17,AC17)
H18: 2 | I18: =AE2 | J18: =AE3 | P18: 15 | Q18: =$AE$26 | R18: 39 | S18: =$AE$27 | X18: 17 | Z18: =MID(Y18,1,9) | AA18: =MID(Y18,11,12) | AC18: =MID(Y18,29,13) | AD18: 17 | AE18: =CONCATENATE(AA18,AB18,AC18)
P19: 16 | Q19: =$AE$28 | R19: 40 | S19: =$AE$29 | X19: 18 | Z19: =MID(Y19,1,9) | AA19: =MID(Y19,11,12) | AC19: =MID(Y19,29,13) | AD19: 18 | AE19: =CONCATENATE(AA19,AB19,AC19)
P20: 17 | Q20: =$AE$30 | R20: 41 | S20: =$AE$31 | X20: 19 | Z20: =MID(Y20,1,9) | AA20: =MID(Y20,11,12) | AC20: =MID(Y20,29,13) | AD20: 19 | AE20: =CONCATENATE(AA20,AB20,AC20)
A21: Medium BCP with 1 splitter | H21: SMALL BEP with 1 splitter | P21: 18 | Q21: =$AE$32 | R21: 42 | S21: =$AE$33 | X21: 20 | Z21: =MID(Y21,1,9) | AA21: =MID(Y21,11,12) | AC21: =MID(Y21,29,13) | AD21: 20 | AE21: =CONCATENATE(AA21,AB21,AC21)
A22: ΘΕΣΗ | B22: Α | C22: ΘΕΣΗ | D22: Β | E22: ΠΑΡΑΤΗΡΗΣΕΙΣ | H22: ΘΕΣΗ | I22: 1 | J22: 2 | K22: 3 | L22: 4 | M22: ΠΑΡΑΤΗΡΗΣΕΙΣ | P22: 19 | Q22: =$AE$34 | R22: 43 | S22: =$AE$35 | T22: χωρίς ports | X22: 21 | Z22: =MID(Y22,1,9) | AA22: =MID(Y22,11,12) | AC22: =MID(Y22,29,13) | AD22: 21 | AE22: =CONCATENATE(AA22,AB22,AC22)
A23: 1 | C23: 1 | E23: από καμπίνα | H23: 1 | K23: =AE2 | L23: =AE3 | P23: 20 | Q23: =AE36 | R23: 44 | S23: =$AE$37 | T23: χωρίς ports | X23: 22 | Z23: =MID(Y23,1,9) | AA23: =MID(Y23,11,12) | AC23: =MID(Y23,29,13) | AD23: 22 | AE23: =CONCATENATE(AA23,AB23,AC23)
A24: 2 | C24: 2 | P24: 21 | Q24: - | R24: 45 | S24: - | T24: χωρίς ports | X24: 23 | Z24: =MID(Y24,1,9) | AA24: =MID(Y24,11,12) | AC24: =MID(Y24,29,13) | AD24: 23 | AE24: =CONCATENATE(AA24,AB24,AC24)
A25: 3 | C25: 3 | P25: 22 | Q25: - | R25: 46 | S25: - | T25: χωρίς ports | X25: 24 | Z25: =MID(Y25,1,9) | AA25: =MID(Y25,11,12) | AC25: =MID(Y25,29,13) | AD25: 24 | AE25: =CONCATENATE(AA25,AB25,AC25)
A26: 4 | C26: 4 | H26: SMALL BCP with 1 splitter | P26: 23 | Q26: - | R26: 47 | S26: - | T26: χωρίς ports | X26: 25 | Z26: =MID(Y26,1,9) | AA26: =MID(Y26,11,12) | AC26: =MID(Y26,29,13) | AD26: 25 | AE26: =CONCATENATE(AA26,AB26,AC26)
A27: 5 | C27: 5 | H27: ΘΕΣΗ | I27: 1 | J27: 2 | K27: 3 | L27: 4 | M27: ΠΑΡΑΤΗΡΗΣΕΙΣ | P27: 24 | Q27: - | R27: 48 | S27: - | T27: χωρίς ports | X27: 26 | Z27: =MID(Y27,1,9) | AA27: =MID(Y27,11,12) | AC27: =MID(Y27,29,13) | AD27: 26 | AE27: =CONCATENATE(AA27,AB27,AC27)
A28: 6 | C28: 6 | H28: 1 | X28: 27 | Z28: =MID(Y28,1,9) | AA28: =MID(Y28,11,12) | AC28: =MID(Y28,29,13) | AD28: 27 | AE28: =CONCATENATE(AA28,AB28,AC28)
A29: 7 | C29: 7 | D29: - | E29: χωρίς ports | X29: 28 | Z29: =MID(Y29,1,9) | AA29: =MID(Y29,11,12) | AC29: =MID(Y29,29,13) | AD29: 28 | AE29: =CONCATENATE(AA29,AB29,AC29)
A30: 8 | B30: - | C30: 8 | D30: - | E30: χωρίς ports | X30: 29 | Z30: =MID(Y30,1,9) | AA30: =MID(Y30,11,12) | AC30: =MID(Y30,29,13) | AD30: 29 | AE30: =CONCATENATE(AA30,AB30,AC30)
X31: 30 | Z31: =MID(Y31,1,9) | AA31: =MID(Y31,11,12) | AC31: =MID(Y31,29,13) | AD31: 30 | AE31: =CONCATENATE(AA31,AB31,AC31)
X32: 31 | Z32: =MID(Y32,1,9) | AA32: =MID(Y32,11,12) | AC32: =MID(Y32,29,13) | AD32: 31 | AE32: =CONCATENATE(AA32,AB32,AC32)
H33: SMALL BMO | X33: 32 | Z33: =MID(Y33,1,9) | AA33: =MID(Y33,11,12) | AC33: =MID(Y33,29,13) | AD33: 32 | AE33: =CONCATENATE(AA33,AB33,AC33)
H34: ΘΕΣΗ | J34: ΠΑΡΑΤΗΡΗΣΕΙΣ | X34: 33 | Z34: =MID(Y34,1,9) | AA34: =MID(Y34,11,12) | AC34: =MID(Y34,29,13) | AD34: 33 | AE34: =CONCATENATE(AA34,AB34,AC34)
H35: A1 | I35: =AE2 | X35: 34 | Z35: =MID(Y35,1,9) | AA35: =MID(Y35,11,12) | AC35: =MID(Y35,29,13) | AD35: 34 | AE35: =CONCATENATE(AA35,AB35,AC35)
H36: B1 | I36: =AE3 | X36: 35 | Z36: =MID(Y36,1,9) | AA36: =MID(Y36,11,12) | AC36: =MID(Y36,29,13) | AD36: 35 | AE36: =CONCATENATE(AA36,AB36,AC36)
H37: C1 | I37: =AE4 | X37: 36 | Z37: =MID(Y37,1,9) | AA37: =MID(Y37,11,12) | AC37: =MID(Y37,29,13) | AD37: 36 | AE37: =CONCATENATE(AA37,AB37,AC37)
H38: D1 | I38: =AE5 | AA38: =MID(Y38,12,9) | AC38: =MID(Y38,29,9)
AA39: =MID(Y39,12,9) | AC39: =MID(Y39,29,9)
AA40: =MID(Y40,12,9) | AC40: =MID(Y40,29,9)
...

Sheet LABELS BEP 
Y1: OPTICAL PATH | AA1: =MID(Y1,12,9) -> H | AC1: index for bmo
P2: XLARGE BEP with 1 splitter | X2: 1 | AA2: =MID(Y2,12,4) | AB2: =MID(Y2,21,4) | AC2: =MID(Y2,29,13) | AD2: =VLOOKUP(AC2,'LABELS BMO'!Z:AE,6,FALSE) | AF2: 1 | AG2: =CONCATENATE(AA2,AB2,AD2,"_",AC2) -> _
A3: Medium BEP with 1 splitter | H3: LARGE BEP with 1 splitter | P3: ΘΕΣΗ | Q3: A | R3: ΘΕΣΗ | S3: B | T3: ΠΑΡΑΤΗΡΗΣΕΙΣ | X3: 2 | AA3: =MID(Y3,12,4) | AB3: =MID(Y3,21,4) | AC3: =MID(Y3,29,13) | AD3: =VLOOKUP(AC3,'LABELS BMO'!Z:AE,6,FALSE) | AF3: 2 | AG3: =CONCATENATE(AA3,AB3,AD3,"_",AC3) -> _
A4: ΘΕΣΗ | B4: Α | C4: ΘΕΣΗ | D4: Β | E4: ΠΑΡΑΤΗΡΗΣΕΙΣ | H4: ΘΕΣΗ | I4: A | J4: B | K4: C | L4: D | M4: ΠΑΡΑΤΗΡΗΣΕΙΣ | P4: 1 | Q4: 1 | R4: 25 | S4: 2 | T4: από καμπίνα | X4: 3 | AA4: =MID(Y4,12,4) | AB4: =MID(Y4,21,4) | AC4: =MID(Y4,29,13) | AD4: =VLOOKUP(AC4,'LABELS BMO'!Z:AE,6,FALSE) | AF4: 3 | AG4: =CONCATENATE(AA4,AB4,AD4,"_",AC4) -> _
A5: 1 | B5: 1 | C5: 1 | D5: 2 | E5: από καμπίνα | H5: 1 | M5: από καμπίνα | P5: 2 | Q5: 3 | R5: 26 | S5: 4 | X5: 4 | AA5: =MID(Y5,12,4) | AB5: =MID(Y5,21,4) | AC5: =MID(Y5,29,13) | AD5: =VLOOKUP(AC5,'LABELS BMO'!Z:AE,6,FALSE) | AF5: 4 | AG5: =CONCATENATE(AA5,AB5,AD5,"_",AC5) -> _
A6: 2 | B6: 3 | C6: 2 | D6: 4 | H6: 2 | I6: =AG2 -> _ | J6: =AG3 -> _ | K6: =AG4 -> _ | L6: =AG5 -> _ | P6: 3 | Q6: =$AG$2 -> _ | R6: 27 | S6: =$AG$3 -> _ | X6: 5 | AA6: =MID(Y6,12,4) | AB6: =MID(Y6,21,4) | AC6: =MID(Y6,29,13) | AD6: =VLOOKUP(AC6,'LABELS BMO'!Z:AE,6,FALSE) | AF6: 5 | AG6: =CONCATENATE(AA6,AB6,AD6,"_",AC6) -> _
A7: 3 | B7: =AG2 -> _ | C7: 3 | D7: =AG3 -> _ | H7: 3 | I7: =AG6 -> _ | J7: =AG7 -> _ | K7: =AG8 -> _ | L7: =AG9 -> _ | P7: 4 | Q7: =$AG$4 -> _ | R7: 28 | S7: =$AG$5 -> _ | X7: 6 | AA7: =MID(Y7,12,4) | AB7: =MID(Y7,21,4) | AC7: =MID(Y7,29,13) | AD7: =VLOOKUP(AC7,'LABELS BMO'!Z:AE,6,FALSE) | AF7: 6 | AG7: =CONCATENATE(AA7,AB7,AD7,"_",AC7) -> _
A8: 4 | B8: =AG4 -> _ | C8: 4 | D8: =AG5 -> _ | H8: 4 | I8: =AG10 -> _ | J8: =AG11 -> _ | K8: =AG12 -> _ | L8: =AG13 -> _ | P8: 5 | Q8: =$AG$6 -> _ | R8: 29 | S8: =$AG$7 -> _ | X8: 7 | AA8: =MID(Y8,12,4) | AB8: =MID(Y8,21,4) | AC8: =MID(Y8,29,13) | AD8: =VLOOKUP(AC8,'LABELS BMO'!Z:AE,6,FALSE) | AF8: 7 | AG8: =CONCATENATE(AA8,AB8,AD8,"_",AC8) -> _
A9: 5 | B9: =AG6 -> _ | C9: 5 | D9: =AG7 -> _ | H9: 5 | I9: =AG14 -> _ | J9: =AG15 -> _ | K9: =AG16 -> _ | L9: =AG17 -> _ | P9: 6 | Q9: =$AG$8 -> _ | R9: 30 | S9: =$AG$9 -> _ | X9: 8 | AA9: =MID(Y9,12,4) | AB9: =MID(Y9,21,4) | AC9: =MID(Y9,29,13) | AD9: =VLOOKUP(AC9,'LABELS BMO'!Z:AE,6,FALSE) | AF9: 8 | AG9: =CONCATENATE(AA9,AB9,AD9,"_",AC9) -> _
A10: 6 | B10: =AG8 -> _ | C10: 6 | D10: =AG9 -> _ | H10: 6 | I10: =AG18 -> _ | J10: =AG19 -> _ | K10: =AG20 | L10: =AG21 | P10: 7 | Q10: =$AG$10 -> _ | R10: 31 | S10: =$AG$11 -> _ | X10: 9 | AA10: =MID(Y10,12,4) | AB10: =MID(Y10,21,4) | AC10: =MID(Y10,29,13) | AD10: =VLOOKUP(AC10,'LABELS BMO'!Z:AE,6,FALSE) | AF10: 9 | AG10: =CONCATENATE(AA10,AB10,AD10,"_",AC10) -> _
A11: 7 | B11: - | C11: 7 | D11: - | E11: χωρίς ports | H11: 7 | I11: =AG22 | J11: =AG23 | K11: =AG24 | L11: =AG25 | P11: 8 | Q11: =$AG$12 -> _ | R11: 32 | S11: =$AG$13 -> _ | X11: 10 | AA11: =MID(Y11,12,4) | AB11: =MID(Y11,21,4) | AC11: =MID(Y11,29,13) | AD11: =VLOOKUP(AC11,'LABELS BMO'!Z:AE,6,FALSE) | AF11: 10 | AG11: =CONCATENATE(AA11,AB11,AD11,"_",AC11) -> _
A12: 8 | B12: - | C12: 8 | D12: - | E12: χωρίς ports | H12: 8 | I12: =AG26 | J12: =AG27 | K12: =AG28 | L12: =AG29 | P12: 9 | Q12: =$AG$14 -> _ | R12: 33 | S12: =$AG$15 -> _ | X12: 11 | AA12: =MID(Y12,12,4) | AB12: =MID(Y12,21,4) | AC12: =MID(Y12,29,13) | AD12: =VLOOKUP(AC12,'LABELS BMO'!Z:AE,6,FALSE) | AF12: 11 | AG12: =CONCATENATE(AA12,AB12,AD12,"_",AC12) -> _
H13: 9 | I13: =AG30 | J13: =AG31 | K13: =AG32 | L13: =AG33 | P13: 10 | Q13: =$AG$16 -> _ | R13: 34 | S13: =$AG$17 -> _ | X13: 12 | AA13: =MID(Y13,12,4) | AB13: =MID(Y13,21,4) | AC13: =MID(Y13,29,13) | AD13: =VLOOKUP(AC13,'LABELS BMO'!Z:AE,6,FALSE) | AF13: 12 | AG13: =CONCATENATE(AA13,AB13,AD13,"_",AC13) -> _
P14: 11 | Q14: =$AG$18 -> _ | R14: 35 | S14: =$AG$19 -> _ | X14: 13 | AA14: =MID(Y14,12,4) | AB14: =MID(Y14,21,4) | AC14: =MID(Y14,29,13) | AD14: =VLOOKUP(AC14,'LABELS BMO'!Z:AE,6,FALSE) | AF14: 13 | AG14: =CONCATENATE(AA14,AB14,AD14,"_",AC14) -> _
H15: SMALL BEP with 1 splitter | P15: 12 | Q15: =$AG$20 | R15: 36 | S15: =$AG$21 | X15: 14 | AA15: =MID(Y15,12,4) | AB15: =MID(Y15,21,4) | AC15: =MID(Y15,29,13) | AD15: =VLOOKUP(AC15,'LABELS BMO'!Z:AE,6,FALSE) | AF15: 14 | AG15: =CONCATENATE(AA15,AB15,AD15,"_",AC15) -> _
H16: ΘΕΣΗ | I16: A | J16: B | K16: ΠΑΡΑΤΗΡΗΣΕΙΣ | P16: 13 | Q16: =$AG$22 | R16: 37 | S16: =$AG$23 | X16: 15 | AA16: =MID(Y16,12,4) | AB16: =MID(Y16,21,4) | AC16: =MID(Y16,29,13) | AD16: =VLOOKUP(AC16,'LABELS BMO'!Z:AE,6,FALSE) | AF16: 15 | AG16: =CONCATENATE(AA16,AB16,AD16,"_",AC16) -> _
H17: 1 | P17: 14 | Q17: =$AG$24 | R17: 38 | S17: =$AG$25 | X17: 16 | AA17: =MID(Y17,12,4) | AB17: =MID(Y17,21,4) | AC17: =MID(Y17,29,13) | AD17: =VLOOKUP(AC17,'LABELS BMO'!Z:AE,6,FALSE) | AF17: 16 | AG17: =CONCATENATE(AA17,AB17,AD17,"_",AC17) -> _
H18: 2 | I18: =AG2 -> _ | J18: =AG3 -> _ | P18: 15 | Q18: =$AG$26 | R18: 39 | S18: =$AG$27 | X18: 17 | AA18: =MID(Y18,12,4) | AB18: =MID(Y18,21,4) | AC18: =MID(Y18,29,13) | AD18: =VLOOKUP(AC18,'LABELS BMO'!Z:AE,6,FALSE) | AF18: 17 | AG18: =CONCATENATE(AA18,AB18,AD18,"_",AC18) -> _
P19: 16 | Q19: =$AG$28 | R19: 40 | S19: =$AG$29 | X19: 18 | AA19: =MID(Y19,12,4) | AB19: =MID(Y19,21,4) | AC19: =MID(Y19,29,13) | AD19: =VLOOKUP(AC19,'LABELS BMO'!Z:AE,6,FALSE) | AF19: 18 | AG19: =CONCATENATE(AA19,AB19,AD19,"_",AC19) -> _
P20: 17 | Q20: =$AG$30 | R20: 41 | S20: =$AG$31 | X20: 19 | AA20: =MID(Y20,12,4) | AB20: =MID(Y20,21,4) | AC20: =MID(Y20,29,13) | AF20: 19 | AG20: =CONCATENATE(AA20,AB20,AC20)
A21: Medium BCP with 1 splitter | H21: SMALL BEP with 1 splitter | P21: 18 | Q21: =$AG$32 | R21: 42 | S21: =$AG$33 | X21: 20 | AA21: =MID(Y21,12,4) | AB21: =MID(Y21,21,4) | AC21: =MID(Y21,29,13) | AF21: 20 | AG21: =CONCATENATE(AA21,AB21,AC21)
A22: ΘΕΣΗ | B22: Α | C22: ΘΕΣΗ | D22: Β | E22: ΠΑΡΑΤΗΡΗΣΕΙΣ | H22: ΘΕΣΗ | I22: 1 | J22: 2 | K22: 3 | L22: 4 | M22: ΠΑΡΑΤΗΡΗΣΕΙΣ | P22: 19 | Q22: =$AG$36 | R22: 43 | S22: =$AG$35 | T22: χωρίς ports | X22: 21 | AA22: =MID(Y22,12,4) | AC22: =MID(Y22,29,13) | AF22: 21 | AG22: =CONCATENATE(AA22,AB22,AC22)
A23: 1 | C23: 1 | E23: από καμπίνα | H23: 1 | K23: =AG2 -> _ | L23: =AG3 -> _ | P23: 20 | Q23: - | R23: 44 | S23: =$AG$37 | T23: χωρίς ports | X23: 22 | AA23: =MID(Y23,12,4) | AB23: =MID(Y23,21,4) | AC23: =MID(Y23,29,13) | AF23: 22 | AG23: =CONCATENATE(AA23,AB23,AC23)
A24: 2 | C24: 2 | P24: 21 | Q24: - | R24: 45 | S24: - | T24: χωρίς ports | X24: 23 | AA24: =MID(Y24,12,4) | AB24: =MID(Y24,21,4) | AC24: =MID(Y24,29,13) | AF24: 23 | AG24: =CONCATENATE(AA24,AB24,AC24)
A25: 3 | C25: 3 | P25: 22 | Q25: - | R25: 46 | S25: - | T25: χωρίς ports | X25: 24 | AA25: =MID(Y25,12,4) | AB25: =MID(Y25,21,4) | AC25: =MID(Y25,29,13) | AF25: 24 | AG25: =CONCATENATE(AA25,AB25,AC25)
A26: 4 | C26: 4 | H26: SMALL BCP with 1 splitter | P26: 23 | Q26: - | R26: 47 | S26: - | T26: χωρίς ports | X26: 25 | AA26: =MID(Y26,12,4) | AB26: =MID(Y26,21,4) | AC26: =MID(Y26,29,13) | AF26: 25 | AG26: =CONCATENATE(AA26,AB26,AC26)
A27: 5 | C27: 5 | H27: ΘΕΣΗ | I27: 1 | J27: 2 | K27: 3 | L27: 4 | M27: ΠΑΡΑΤΗΡΗΣΕΙΣ | P27: 24 | Q27: - | R27: 48 | S27: - | T27: χωρίς ports | X27: 26 | AA27: =MID(Y27,12,4) | AB27: =MID(Y27,21,4) | AC27: =MID(Y27,29,13) | AF27: 26 | AG27: =CONCATENATE(AA27,AB27,AC27)
A28: 6 | C28: 6 | H28: 1 | X28: 27 | AA28: =MID(Y28,12,4) | AB28: =MID(Y28,21,4) | AC28: =MID(Y28,29,13) | AF28: 27 | AG28: =CONCATENATE(AA28,AB28,AC28)
A29: 7 | C29: 7 | D29: - | E29: χωρίς ports | X29: 28 | AA29: =MID(Y29,12,4) | AB29: =MID(Y29,21,4) | AC29: =MID(Y29,29,13) | AF29: 28 | AG29: =CONCATENATE(AA29,AB29,AC29)
A30: 8 | B30: - | C30: 8 | D30: - | E30: χωρίς ports | X30: 29 | AA30: =MID(Y30,12,4) | AB30: =MID(Y30,21,4) | AC30: =MID(Y30,29,13) | AF30: 29 | AG30: =CONCATENATE(AA30,AB30,AC30)
H31: SMALL BCP with 1 splitter ZTT | X31: 30 | AA31: =MID(Y31,12,4) | AB31: =MID(Y31,21,4) | AC31: =MID(Y31,29,13) | AF31: 30 | AG31: =CONCATENATE(AA31,AB31,AC31)
H32: ΘΕΣΗ | I32: - | J32: ΠΑΡΑΤΗΡΗΣΕΙΣ | X32: 31 | AA32: =MID(Y32,12,4) | AB32: =MID(Y32,21,4) | AC32: =MID(Y32,29,13) | AF32: 31 | AG32: =CONCATENATE(AA32,AB32,AC32)
H33: 1 | X33: 32 | AA33: =MID(Y33,12,4) | AB33: =MID(Y33,21,4) | AC33: =MID(Y33,29,13) | AF33: 32 | AG33: =CONCATENATE(AA33,AB33,AC33)
H34: 2 | X34: 33 | AA34: =MID(Y34,12,4) | AB34: =MID(Y34,21,4) | AC34: =MID(Y34,29,13) | AF34: 33 | AG34: =CONCATENATE(AA34,AB34,AC34)
H35: 3 | X35: 34 | AA35: =MID(Y35,12,4) | AB35: =MID(Y35,21,4) | AC35: =MID(Y35,29,13) | AF35: 34 | AG35: =CONCATENATE(AA35,AB35,AC35)
H36: 4 | X36: 35 | AA36: =MID(Y36,12,4) | AB36: =MID(Y36,21,4) | AC36: =MID(Y36,29,13) | AF36: 35 | AG36: =CONCATENATE(AA36,AB36,AC36)
X37: 36 | AA37: =MID(Y37,12,4) | AB37: =MID(Y37,21,4) | AC37: =MID(Y37,29,13) | AF37: 36 | AG37: =CONCATENATE(AA37,AB37,AC37)
AA38: =MID(Y38,12,9) | AC38: =MID(Y38,29,9)
AA39: =MID(Y39,12,9) | AC39: =MID(Y39,29,9)
AA40: =MID(Y40,12,9) | AC40: =MID(Y40,29,9)
...

Sheet AS build-Επιμέτρηση
U1: Τύπος | V1: ΤΥΠΟΣ ΚΟΙ | W1: ΣΗΜΕΙΟ ΤΟΠΟΘΕΤΗΣΗΣ | X1: ΕΙΔΟΣ | Y1: Είδος κάθετης υποδομής | Z1: FIRST BOX | AA1: ΕΙΔΟΣ ΥΠΟΔΟΜΗΣ | AB1: ΟΡΟΦΟΣ | AC1: ΤΥΠΟΣ ΚΟΙ ΣΥΝΔΕΣΗ ΒCP ΜΕ BEP | AD1: ΝΕΑ ΑΠΟΜΑΣΤΕΥΣΗ
U2: RETAIL | V2: 4' μ cable | W2: BCP ΕΠΙ ΤΟΥ ΚΤΙΡΙΟΥ | X2: BCP ΝΕΟ | Y2: ΚΑΓΚΕΛΟ | Z2: BEP | AA2: ΝΕΑ ΥΠΟΔΟΜΗ | AB2: ΥΠ 2 | AC2: 4 FO G652D | AD2: ΝΑΙ
B3: 0 ΣΤΟΙΧΕΙΑ ΑΙΤΗΜΑΤΟΣ | U3: WHOLESALE | V3: 12' μ cable | W3: BCP ΕΠΙ ΡΥΜΟΤΟΜΙΚΗΣ | X3: ΥΦΙΣΤΑΜΕΝΟ | Y3: ΚΛΙΜΑΚΟΣΤΑΣΙΟ | Z3: BCP | AA3: ΕΣΚΑΛΗΤ | AB3: ΥΠ 1 | AC3: 12 FO G652D | AD3: ΌΧΙ
B4: Τύπος | D4: Κατηγορία | E4: SR | F4: ΔΙΕΥΘΥΝΣΗ | R4: ΑΚ | U4: WHOLEBUY | V4: 12'= 4 μ cable | W4: BCP ΣΤΥΛΟΣ | X4: ΥΦΙΣΤΑΜΕΝΟ ενεργό | Y4: ΕΞΩΤΕΡΙΚΑ ΕΠΙΤΟΙΧΙΑ: | AA4: BCP | AB4: ΥΠ | AC4: Aerial flat drop cable 2 FΟ
B5: PILOT | D5: RETAIL | E5: =B8 -> 2-339414353721 | F5: ΚΑΡΑΟΛΗ ΚΑΙ ΔΗΜΗΤΡΙΟΥ 12 | R5: ΠΕΡΑ | V5: 12' =8 μ cable | Y5: ΦΩΤΑΓΩΓΟΣ: | AB5: ΗΜΥ | AC5: 2 FO G657A
B6: 1 ΚΤΗΡΙΟ | Y6: ΑΛΛΟ | AB6: ΙΣ
B7: SRId | C7: BUILDING ID | D7: AREA TYPE | E7: ΟΡΟΦΟΙ | F7: ΟΡΟΦΟΣ ΠΕΛΑΤΗ | G7: ΟΡΟΦΟΣ BEP | H7: ΥΠΟΓΡΑΦΗ ΔΙΑΧΕΙΡΙΣΤΗ | I7: BEP ONLY | J7: BEP TEMPLATE | K7: BEP TYPE | L7: BMO TYPE | M7: NANOTRONIX | N7: SMART READINESS | O7: ΣΥΣΧΕΤΙΣΜΕΝΟ BCP | P7: ΚΟΝΤΙΝΟ BCP | Q7: ΝΕΟ BCP | R7: CONDUIT | AB7: ΗΜ
A8: COPY PASTE VALUES FROM TAB ΚΤΗΡΙΟ | B8: 2-339414353721 | C8: 754086020 | D8: OTE | E8: 5 | F8: +03 | G8: +00 | H8: TRUE | I8: FALSE | J8: BEP 4SP 1:8(01a..09d) ΟΔ | K8: X-LARGE/48/RAYCAP | L8: LARGE/80/RAYCAP | M8: FALSE | N8: FALSE | O8: FALSE | R8: b09 | AB8: 1ος
AB9: 2ος
B10: 2 KOI CAB first box ( BEP ή BCP) | AB10: 3ος | AC10: 2
AB11: 4ος | AC11: 4
D12: FIRST BOX | E12: ΤΥΠΟΣ ΚΟΙ | F12: ΜΗΚΟΣ (m) | AB12: 5ος
D13: BEP | E13: 4' μ cable | F13: 314 | AB13: 6ος
AB14: 7ος
B15: 3. KOI BCP--BEP
AB16: 8ος
D17: ΣΗΜΕΙΟ ΤΟΠΟΘΕΤΗΣΗΣ | E17: ΕΙΔΟΣ | F17: ΤΥΠΟΣ ΚΟΙ ΣΥΝΔΕΣΗ ΒCP ΜΕ BEP | G17: ΜΗΚΟΣ (m) | AB17: 9ος
D18: ΣΗΜΕΙΟ ΤΟΠΟΘΕΤΗΣΗΣ | E18: ΕΙΔΟΣ | F18: 4 FO G652D | AB18: 10ος
AB19: 11ος
B20: 4. BEP-ΟΡΟΦΟΙ
B22: ΟΡΟΦΟΣ ΤΟΠΟΘΕΤΗΣΗΣ ΒΕΡ | C22: ΙΣ | D22: ΚΛΙΜΑΚΟΣΤΑΣΙΟ
B24: ΟΡΟΦΟΣ | C24: ΔΙΑΜΕΡΙΣΜΑΤΑ | D24: ΚΑΤΑΣΤΗΜΑΤΑ | E24: FB01 | F24: FB01 TYPE | G24: FB02 | H24: FB02 TYPE | I24: FB ΠΕΛΑΤΗ | J24: ΔΙΑΜΕΡΙΣΜΑ ΠΕΛΑΤΗ | K24: GIS ID | L24: FB04 TYPE | M24: FB ΠΕΛΑΤΗ | N24: ΑΡΙΘΜΗΣΗ ΧΩΡΟΥ ΠΕΛΑΤΗ | O24: GIS ID | P24: ΜΕΤΡΑ | Q24: ΕΙΔΟΣ 2'',4",12"
A25: COPY PASTE VALUES FROM ΤΑΒ ΟΡΟΦΟΙ | B25: -01 | C25: 0 | D25: 0
B26: +00 | C26: 0 | D26: 8 | E26: 6 | F26: FB 12 PORTS | G26: 2 | H26: FB 12 PORTS | P26: 25+20 | Q26: 12+12
B27: +01 | C27: 6 | D27: 0 | E27: 6 | F27: FB 12 PORTS | P27: 20 | Q27: 12
B28: +02 | C28: 6 | D28: 0 | E28: 6 | F28: FB 12 PORTS | P28: 23 | Q28: 12
B29: +03 | C29: 6 | D29: 0 | E29: 6 | F29: FB 12 PORTS | M29: FB(+03).1 | N29: Γ1 | P29: 26 | Q29: 12
B42: 5. ΣΤΟΙΧΕΙΑ ΚΑΜΠΙΝΑΣ/ LABEL BEP/BCP | S42: 5. ΣΤΟΙΧΕΙΑ BMO
F43: OPTICAL PATH TYPE | G43: OPTICAL PATH
A44: COPY PASTE VALUES FROM TAB OPTICAL PATHS ( CAB-BEP, CAB-BCP,BCP-BEP) | F44: CAB-BEP | G44: G489_SGA03(1:8).02_B1.9_BEP01(b09)_01a_SB01(1:8)
F45: CAB-BEP | G45: G489_SGA03(1:8).03_B1.10_BEP01(b09)_01b_SB02(1:8)
F46: CAB-BEP | G46: G489_SGA03(1:8).04_B1.11_BEP01(b09)_01c_SB03(1:8)
F47: CAB-BEP | G47: G489_SGA03(1:8).05_B1.12_BEP01(b09)_01d_SB04(1:8)
C49: ΘΕΣΗ | D49: A | E49: B | F49: C | G49: D | H49: ΠΑΡΑΤΗΡΗΣΕΙΣ
C50: 1 | H50: από καμπίνα
C51: 2 | D51: =AC47 -> 0 | E51: =AC48 -> 0 | F51: =AB49 -> 0 | G51: =AB50 -> 0
C52: 3 | D52: =AB51 -> 0 | E52: =AB52 -> 0 | F52: =AB53 -> 0 | G52: =AB54 -> 0
C53: 4 | D53: =AB55 -> 0 | E53: =AB56 -> 0 | F53: =AB57 -> 0 | G53: =AB58 -> 0
C54: 5 | D54: =AB59 -> 0 | E54: =AB60 -> 0 | F54: =AB61 -> 0
C55: 6 | D55: =AB63 -> 0 | E55: =AB64 -> 0 | F55: =AB65 -> 0 | G55: =AB66 -> 0
...
